{
 "cells": [
  {
   "cell_type": "code",
   "execution_count": null,
   "id": "a267855f",
   "metadata": {},
   "outputs": [
    {
     "ename": "KeyError",
     "evalue": "0",
     "output_type": "error",
     "traceback": [
      "\u001b[1;31m---------------------------------------------------------------------------\u001b[0m",
      "\u001b[1;31mKeyError\u001b[0m                                  Traceback (most recent call last)",
      "File \u001b[1;32mc:\\anaconda3\\Lib\\site-packages\\pandas\\core\\indexes\\base.py:3805\u001b[0m, in \u001b[0;36mIndex.get_loc\u001b[1;34m(self, key)\u001b[0m\n\u001b[0;32m   3804\u001b[0m \u001b[38;5;28;01mtry\u001b[39;00m:\n\u001b[1;32m-> 3805\u001b[0m     \u001b[38;5;28;01mreturn\u001b[39;00m \u001b[38;5;28mself\u001b[39m\u001b[38;5;241m.\u001b[39m_engine\u001b[38;5;241m.\u001b[39mget_loc(casted_key)\n\u001b[0;32m   3806\u001b[0m \u001b[38;5;28;01mexcept\u001b[39;00m \u001b[38;5;167;01mKeyError\u001b[39;00m \u001b[38;5;28;01mas\u001b[39;00m err:\n",
      "File \u001b[1;32mindex.pyx:167\u001b[0m, in \u001b[0;36mpandas._libs.index.IndexEngine.get_loc\u001b[1;34m()\u001b[0m\n",
      "File \u001b[1;32mindex.pyx:196\u001b[0m, in \u001b[0;36mpandas._libs.index.IndexEngine.get_loc\u001b[1;34m()\u001b[0m\n",
      "File \u001b[1;32mpandas\\\\_libs\\\\hashtable_class_helper.pxi:7081\u001b[0m, in \u001b[0;36mpandas._libs.hashtable.PyObjectHashTable.get_item\u001b[1;34m()\u001b[0m\n",
      "File \u001b[1;32mpandas\\\\_libs\\\\hashtable_class_helper.pxi:7089\u001b[0m, in \u001b[0;36mpandas._libs.hashtable.PyObjectHashTable.get_item\u001b[1;34m()\u001b[0m\n",
      "\u001b[1;31mKeyError\u001b[0m: 0",
      "\nThe above exception was the direct cause of the following exception:\n",
      "\u001b[1;31mKeyError\u001b[0m                                  Traceback (most recent call last)",
      "Cell \u001b[1;32mIn[8], line 7\u001b[0m\n\u001b[0;32m      4\u001b[0m df \u001b[38;5;241m=\u001b[39m pd\u001b[38;5;241m.\u001b[39mread_csv(\u001b[38;5;124m'\u001b[39m\u001b[38;5;124mdiario.csv\u001b[39m\u001b[38;5;124m'\u001b[39m)\n\u001b[0;32m      6\u001b[0m \u001b[38;5;66;03m# Acessa o valor na linha 0, coluna 'Nome'\u001b[39;00m\n\u001b[1;32m----> 7\u001b[0m valor \u001b[38;5;241m=\u001b[39m df\u001b[38;5;241m.\u001b[39mloc[\u001b[38;5;241m0\u001b[39m, \u001b[38;5;124m'\u001b[39m\u001b[38;5;124mhora\u001b[39m\u001b[38;5;124m'\u001b[39m]\n\u001b[0;32m      8\u001b[0m \u001b[38;5;28mprint\u001b[39m(valor)\n",
      "File \u001b[1;32mc:\\anaconda3\\Lib\\site-packages\\pandas\\core\\indexing.py:1183\u001b[0m, in \u001b[0;36m_LocationIndexer.__getitem__\u001b[1;34m(self, key)\u001b[0m\n\u001b[0;32m   1181\u001b[0m     key \u001b[38;5;241m=\u001b[39m \u001b[38;5;28mtuple\u001b[39m(com\u001b[38;5;241m.\u001b[39mapply_if_callable(x, \u001b[38;5;28mself\u001b[39m\u001b[38;5;241m.\u001b[39mobj) \u001b[38;5;28;01mfor\u001b[39;00m x \u001b[38;5;129;01min\u001b[39;00m key)\n\u001b[0;32m   1182\u001b[0m     \u001b[38;5;28;01mif\u001b[39;00m \u001b[38;5;28mself\u001b[39m\u001b[38;5;241m.\u001b[39m_is_scalar_access(key):\n\u001b[1;32m-> 1183\u001b[0m         \u001b[38;5;28;01mreturn\u001b[39;00m \u001b[38;5;28mself\u001b[39m\u001b[38;5;241m.\u001b[39mobj\u001b[38;5;241m.\u001b[39m_get_value(\u001b[38;5;241m*\u001b[39mkey, takeable\u001b[38;5;241m=\u001b[39m\u001b[38;5;28mself\u001b[39m\u001b[38;5;241m.\u001b[39m_takeable)\n\u001b[0;32m   1184\u001b[0m     \u001b[38;5;28;01mreturn\u001b[39;00m \u001b[38;5;28mself\u001b[39m\u001b[38;5;241m.\u001b[39m_getitem_tuple(key)\n\u001b[0;32m   1185\u001b[0m \u001b[38;5;28;01melse\u001b[39;00m:\n\u001b[0;32m   1186\u001b[0m     \u001b[38;5;66;03m# we by definition only have the 0th axis\u001b[39;00m\n",
      "File \u001b[1;32mc:\\anaconda3\\Lib\\site-packages\\pandas\\core\\frame.py:4221\u001b[0m, in \u001b[0;36mDataFrame._get_value\u001b[1;34m(self, index, col, takeable)\u001b[0m\n\u001b[0;32m   4215\u001b[0m engine \u001b[38;5;241m=\u001b[39m \u001b[38;5;28mself\u001b[39m\u001b[38;5;241m.\u001b[39mindex\u001b[38;5;241m.\u001b[39m_engine\n\u001b[0;32m   4217\u001b[0m \u001b[38;5;28;01mif\u001b[39;00m \u001b[38;5;129;01mnot\u001b[39;00m \u001b[38;5;28misinstance\u001b[39m(\u001b[38;5;28mself\u001b[39m\u001b[38;5;241m.\u001b[39mindex, MultiIndex):\n\u001b[0;32m   4218\u001b[0m     \u001b[38;5;66;03m# CategoricalIndex: Trying to use the engine fastpath may give incorrect\u001b[39;00m\n\u001b[0;32m   4219\u001b[0m     \u001b[38;5;66;03m#  results if our categories are integers that dont match our codes\u001b[39;00m\n\u001b[0;32m   4220\u001b[0m     \u001b[38;5;66;03m# IntervalIndex: IntervalTree has no get_loc\u001b[39;00m\n\u001b[1;32m-> 4221\u001b[0m     row \u001b[38;5;241m=\u001b[39m \u001b[38;5;28mself\u001b[39m\u001b[38;5;241m.\u001b[39mindex\u001b[38;5;241m.\u001b[39mget_loc(index)\n\u001b[0;32m   4222\u001b[0m     \u001b[38;5;28;01mreturn\u001b[39;00m series\u001b[38;5;241m.\u001b[39m_values[row]\n\u001b[0;32m   4224\u001b[0m \u001b[38;5;66;03m# For MultiIndex going through engine effectively restricts us to\u001b[39;00m\n\u001b[0;32m   4225\u001b[0m \u001b[38;5;66;03m#  same-length tuples; see test_get_set_value_no_partial_indexing\u001b[39;00m\n",
      "File \u001b[1;32mc:\\anaconda3\\Lib\\site-packages\\pandas\\core\\indexes\\base.py:3812\u001b[0m, in \u001b[0;36mIndex.get_loc\u001b[1;34m(self, key)\u001b[0m\n\u001b[0;32m   3807\u001b[0m     \u001b[38;5;28;01mif\u001b[39;00m \u001b[38;5;28misinstance\u001b[39m(casted_key, \u001b[38;5;28mslice\u001b[39m) \u001b[38;5;129;01mor\u001b[39;00m (\n\u001b[0;32m   3808\u001b[0m         \u001b[38;5;28misinstance\u001b[39m(casted_key, abc\u001b[38;5;241m.\u001b[39mIterable)\n\u001b[0;32m   3809\u001b[0m         \u001b[38;5;129;01mand\u001b[39;00m \u001b[38;5;28many\u001b[39m(\u001b[38;5;28misinstance\u001b[39m(x, \u001b[38;5;28mslice\u001b[39m) \u001b[38;5;28;01mfor\u001b[39;00m x \u001b[38;5;129;01min\u001b[39;00m casted_key)\n\u001b[0;32m   3810\u001b[0m     ):\n\u001b[0;32m   3811\u001b[0m         \u001b[38;5;28;01mraise\u001b[39;00m InvalidIndexError(key)\n\u001b[1;32m-> 3812\u001b[0m     \u001b[38;5;28;01mraise\u001b[39;00m \u001b[38;5;167;01mKeyError\u001b[39;00m(key) \u001b[38;5;28;01mfrom\u001b[39;00m \u001b[38;5;21;01merr\u001b[39;00m\n\u001b[0;32m   3813\u001b[0m \u001b[38;5;28;01mexcept\u001b[39;00m \u001b[38;5;167;01mTypeError\u001b[39;00m:\n\u001b[0;32m   3814\u001b[0m     \u001b[38;5;66;03m# If we have a listlike key, _check_indexing_error will raise\u001b[39;00m\n\u001b[0;32m   3815\u001b[0m     \u001b[38;5;66;03m#  InvalidIndexError. Otherwise we fall through and re-raise\u001b[39;00m\n\u001b[0;32m   3816\u001b[0m     \u001b[38;5;66;03m#  the TypeError.\u001b[39;00m\n\u001b[0;32m   3817\u001b[0m     \u001b[38;5;28mself\u001b[39m\u001b[38;5;241m.\u001b[39m_check_indexing_error(key)\n",
      "\u001b[1;31mKeyError\u001b[0m: 0"
     ]
    }
   ],
   "source": [
    "import pandas as pd\n",
    "\n",
    "# Carrega o arquivo CSV\n",
    "df = pd.read_csv('diario.csv')\n",
    "\n",
    "# Acessa o valor na linha 0, coluna 'Nome'\n",
    "\n"
   ]
  },
  {
   "cell_type": "code",
   "execution_count": null,
   "id": "b3a8dd56",
   "metadata": {},
   "outputs": [],
   "source": []
  }
 ],
 "metadata": {
  "kernelspec": {
   "display_name": "Python 3",
   "language": "python",
   "name": "python3"
  },
  "language_info": {
   "codemirror_mode": {
    "name": "ipython",
    "version": 3
   },
   "file_extension": ".py",
   "mimetype": "text/x-python",
   "name": "python",
   "nbconvert_exporter": "python",
   "pygments_lexer": "ipython3",
   "version": "3.12.7"
  }
 },
 "nbformat": 4,
 "nbformat_minor": 5
}
